<?xml version="1.0" encoding="utf-8"?>
<!-- =================================================================================== -->
<!-- |    This document was autogenerated by xacro from DianaS1_robot.urdf.xacro       | -->
<!-- |    EDITING THIS FILE BY HAND IS NOT RECOMMENDED                                 | -->
<!-- =================================================================================== -->
<robot name="DianaS1">
  <link name="base_link">
    <inertial>
      <origin rpy="0 0 0" xyz="-0.00025974 -0.00026507 0.024973"/>
      <mass value="1.61"/>
      <inertia ixx="0.0042468" ixy="2.2962E-05" ixz="-7.5575E-06" iyy="0.004245" iyz="-7.4546E-06" izz="0.0072668"/>
    </inertial>
    <visual>
      <origin rpy="0 0 0" yz="0 0 0"/>
      <geometry>
        <mesh filename="package://dianaS1_description/meshes/base_link.STL"/>
      </geometry>
      <material name="LightGrey">
        <color rgba="0.7 0.7 0.7 1"/>
      </material>
    </visual>
    <collision>
      <origin rpy="0 0 0" xyz="0 0 0"/>
      <geometry>
        <mesh filename="package://dianaS1_description/meshes/base_link.STL"/>
      </geometry>
    </collision>
  </link>
  <joint name="joint1" type="revolute">
    <origin rpy="3.14159265359 0 0" xyz="0 0 0.2723"/>
    <parent link="base_link"/>
    <child link="link1"/>
    <axis xyz="0 0 1"/>
    <limit effort="235.0" lower="-3.12413936107" upper="3.12413936107" velocity="3.14159265359"/>
    <dynamics damping="0.0" friction="0.0"/>
  </joint>
  <link name="link1">
    <inertial>
      <origin rpy="0 0 0" xyz="-0.000108043 -0.044600027 0.068607373"/>
      <mass value="6.67548"/>
      <inertia ixx="0.113166041" ixy="-0.00000662439" ixz="0.0000384752" iyy="0.085738172" iyz="-0.0000471067" izz="0.04163282"/>
    </inertial>
    <visual>
      <origin rpy="0 0 0" xyz="0 0 0"/>
      <geometry>
        <mesh filename="package://dianaS1_description/meshes/link1.STL"/>
      </geometry>
      <material name="LightGrey">
        <color rgba="0.7 0.7 0.7 1"/>
      </material>
    </visual>
    <collision>
      <origin rpy="0 0 0" xyz="0 0 0"/>
      <geometry>
        <mesh filename="package://dianaS1_description/meshes/link1.STL"/>
      </geometry>
    </collision>
  </link>
  <joint name="joint2" type="revolute">
    <origin rpy="-1.57079632679 0 0" xyz="0 -0.156 0"/>
    <parent link="link1"/>
    <child link="link2"/>
    <axis xyz="0 0 1"/>
    <limit effort="235.0" lower="-2.79252680319" upper="2.79252680319" velocity="3.14159265359"/>
    <dynamics damping="0.0" friction="0.0"/>
  </joint>
  <link name="link2">
    <inertial>
      <origin rpy="0 0 0" xyz="0.00000875698 0.047132796 0.006996823"/>
      <mass value="3.11643"/>
      <inertia ixx="0.021414698" ixy="-0.0000012365" ixz="0.00000085133" iyy="0.006006288" iyz="0.000151513" izz="0.022441273"/>
    </inertial>
    <visual>
      <origin rpy="0 0 0" xyz="0 0 0"/>
      <geometry>
        <mesh filename="package://dianaS1_description/meshes/link2.STL"/>
      </geometry>
      <material name="LightGrey">
        <color rgba="0.7 0.7 0.7 1"/>
      </material>
    </visual>
    <collision>
      <origin rpy="0 0 0" xyz="0 0 0"/>
      <geometry>
        <mesh filename="package://dianaS1_description/meshes/link2.STL"/>
      </geometry>
    </collision>
  </link>
  <joint name="joint3" type="revolute">
    <origin rpy="1.57079632679 0 0" xyz="0 0.4577 0"/>
    <parent link="link2"/>
    <child link="link3"/>
    <axis xyz="0 0 1"/>
    <limit effort="111.0" lower="-3.12413936107" upper="3.12413936107" velocity="3.14159265359"/>
    <dynamics damping="0.0" friction="0.0"/>
  </joint>
  <link name="link3">
    <inertial>
      <origin rpy="0 0 0" xyz="0.0000183253 0.03187396 0.136688085"/>
      <mass value="4.62614"/>
      <inertia ixx="0.198692057" ixy="0.00000537943" ixz="0.0000108296" iyy="0.187330776" iyz="-0.00026749" izz="0.018225492"/>
    </inertial>
    <visual>
      <origin rpy="0 0 0" xyz="0 0 0"/>
      <geometry>
        <mesh filename="package://dianaS1_description/meshes/link3.STL"/>
      </geometry>
      <material name="LightGrey">
        <color rgba="0.7 0.7 0.7 1"/>
      </material>
    </visual>
    <collision>
      <origin rpy="0 0 0" xyz="0 0 0"/>
      <geometry>
        <mesh filename="package://dianaS1_description/meshes/link3.STL"/>
      </geometry>
    </collision>
  </link>
  <joint name="joint4" type="revolute">
    <origin rpy="1.57079632679 0 0" xyz="0 0.1371 0"/>
    <parent link="link3"/>
    <child link="link4"/>
    <axis xyz="0 0 1"/>
    <limit effort="111.0" lower="-2.79252680319" upper="2.79252680319" velocity="3.14159265359"/>
    <dynamics damping="0.0" friction="0.0"/>
  </joint>
  <link name="link4">
    <inertial>
      <origin rpy="0 0 0" xyz="-0.0000171058 -0.048491536 0.007150206"/>
      <mass value="1.9961"/>
      <inertia ixx="0.012642755" ixy="-0.00000163658" ixz="0.00000012834" iyy="0.002906848" iyz="-0.0000516913" izz="0.012740515"/>
    </inertial>
    <visual>
      <origin rpy="0 0 0" xyz="0 0 0"/>
      <geometry>
        <mesh filename="package://dianaS1_description/meshes/link4.STL"/>
      </geometry>
      <material name="LightGrey">
        <color rgba="0.7 0.7 0.7 1"/>
      </material>
    </visual>
    <collision>
      <origin rpy="0 0 0" xyz="0 0 0"/>
      <geometry>
        <mesh filename="package://dianaS1_description/meshes/link4.STL"/>
      </geometry>
    </collision>
  </link>
  <joint name="joint5" type="revolute">
    <origin rpy="-1.57079632679 0 0" xyz="0 -0.449 0"/>
    <parent link="link4"/>
    <child link="link5"/>
    <axis xyz="0 0 1"/>
    <limit effort="90.0" lower="-3.12413936107" upper="3.12413936107" velocity="3.14159265359"/>
    <dynamics damping="0.0" friction="0.0"/>
  </joint>
  <link name="link5">
    <inertial>
      <origin rpy="0 0 0" xyz="-0.000027456 -0.002120073 0.13041583"/>
      <mass value="3.40632"/>
      <inertia ixx="0.129484072" ixy="0.00000023257" ixz="0.00000830368" iyy="0.128743236" iyz="-0.0000756544" izz="0.004813837"/>
    </inertial>
    <visual>
      <origin rpy="0 0 0" xyz="0 0 0"/>
      <geometry>
        <mesh filename="package://dianaS1_description/meshes/link5.STL"/>
      </geometry>
      <material name="LightGrey">
        <color rgba="0.7 0.7 0.7 1"/>
      </material>
    </visual>
    <collision>
      <origin rpy="0 0 0" xyz="0 0 0"/>
      <geometry>
        <mesh filename="package://dianaS1_description/meshes/link5.STL"/>
      </geometry>
    </collision>
  </link>
  <joint name="joint6" type="revolute">
    <origin rpy="-1.57079632679 0 0" xyz="0 -0.1365 0"/>
    <parent link="link5"/>
    <child link="link6"/>
    <axis xyz="0 0 1"/>
    <limit effort="90.0" lower="-3.12413936107" upper="3.12413936107" velocity="3.14159265359"/>
    <dynamics damping="0.0" friction="0.0"/>
  </joint>
  <link name="link6">
    <inertial>
      <origin rpy="0 0 0" xyz="0.0000262506 0.003206123 0.027090603"/>
      <mass value="2.31124"/>
      <inertia ixx="0.008348207" ixy="-0.00000063196" ixz="-0.0000036489" iyy="0.007600004" iyz="0.0000308886" izz="0.003426032"/>
    </inertial>
    <visual>
      <origin rpy="0 0 0" xyz="0 0 0"/>
      <geometry>
        <mesh filename="package://dianaS1_description/meshes/link6.STL"/>
      </geometry>
      <material name="LightGrey">
        <color rgba="0.7 0.7 0.7 1"/>
      </material>
    </visual>
    <collision>
      <origin rpy="0 0 0" xyz="0 0 0"/>
      <geometry>
        <mesh filename="package://dianaS1_description/meshes/link6.STL"/>
      </geometry>
    </collision>
  </link>
  <joint name="joint7" type="revolute">
    <origin rpy="1.57079632679 0 0" xyz="0 0.0825 0"/>
    <parent link="link6"/>
    <child link="link7"/>
    <axis xyz="0 0 1"/>
    <limit effort="90.0" lower="-3.12413936107" upper="3.12413936107" velocity="3.14159265359"/>
    <dynamics damping="0.0" friction="0.0"/>
  </joint>
  <link name="link7">
    <inertial>
      <origin rpy="0 0 0" xyz="0.0 0.0001 0.03405"/>
      <mass value="0.53497"/>
      <inertia ixx="0.001391424" ixy="-0.0000002188" ixz="0.00000014776" iyy="0.001391382" iyz="-0.00000139675" izz="0.000430176"/>
    </inertial>
    <visual>
      <origin rpy="0 0 0" xyz="0 0 0"/>
      <geometry>
        <mesh filename="package://dianaS1_description/meshes/link7.STL"/>
      </geometry>
      <material name="LightGrey">
        <color rgba="0.7 0.7 0.7 1"/>
      </material>
    </visual>
    <collision>
      <origin rpy="0 0 0" xyz="0 0 0"/>
      <geometry>
        <mesh filename="package://dianaS1_description/meshes/link7.STL"/>
      </geometry>
    </collision>
  </link>
  <link name="world"/>
  <joint name="world_joint" type="fixed">
    <parent link="world"/>
    <child link="base_link"/>
    <origin rpy="0.0 0.0 0.0" xyz="0.0 0.0 0.0"/>
  </joint>
</robot>

